<?xml version="1.0" encoding="utf-8"?>
<!-- This URDF was automatically created by SolidWorks to URDF Exporter! Originally created by Stephen Brawner (brawner@gmail.com) 
     Commit Version: 1.6.0-4-g7f85cfe  Build Version: 1.6.7995.38578
     For more information, please see http://wiki.ros.org/sw_urdf_exporter -->
<robot
  name="ice_cream_0208.SLDASM">
  <link
    name="link0">
    <inertial>
      <origin
        xyz="0.298723185372181 0.125183936781969 -0.113715129178132"
        rpy="0 0 0" />
      <mass
        value="36.7035981731794" />
      <inertia
        ixx="9.73381890786075"
        ixy="0.000160125272711892"
        ixz="2.19564408008489E-07"
        iyy="0.891257414853354"
        iyz="-0.000227508420568495"
        izz="9.5986844838261" />
    </inertial>
    <visual>
      <origin
        xyz="0 0 0"
        rpy="0 0 0" />
      <geometry>
        <mesh
          filename="../meshes/link0.STL" />
      </geometry>
      <material
        name="">
        <color
          rgba="1 1 1 1" />
      </material>
    </visual>
    <collision>
      <origin
        xyz="0 0 0"
        rpy="0 0 0" />
      <geometry>
        <mesh
          filename="../meshes/link0.STL" />
      </geometry>
    </collision>
  </link>
  <link
    name="link1">
    <inertial>
      <origin
        xyz="0.000497391616295806 4.45935440505455E-07 -0.00573159337285223"
        rpy="0 0 0" />
      <mass
        value="0.1489414191866" />
      <inertia
        ixx="7.14443720727287E-05"
        ixy="2.91156160207487E-06"
        ixz="-3.7045419990129E-06"
        iyy="4.5433475868891E-05"
        iyz="-4.54927395596475E-07"
        izz="8.10157446237737E-05" />
    </inertial>
    <visual>
      <origin
        xyz="0 0 0"
        rpy="0 0 0" />
      <geometry>
        <mesh
          filename="../meshes/link1.STL" />
      </geometry>
      <material
        name="">
        <color
          rgba="1 1 1 1" />
      </material>
    </visual>
    <collision>
      <origin
        xyz="0 0 0"
        rpy="0 0 0" />
      <geometry>
        <mesh
          filename="../meshes/link1.STL" />
      </geometry>
    </collision>
  </link>
  <joint
    name="joint1"
    type="revolute">
    <origin
      xyz="0.124999999999995 0.125000000000034 0.1055"
      rpy="0 0 0" />
    <parent
      link="link0" />
    <child
      link="link1" />
    <axis
      xyz="0 0 -1" />
    <limit
      lower="-3.14"
      upper="3.14"
      effort="0"
      velocity="0.1" />
  </joint>
  <link
    name="link2">
    <inertial>
      <origin
        xyz="0.110478393739343 0.0171528156512473 -0.024036698269772"
        rpy="0 0 0" />
      <mass
        value="0.511219040543558" />
      <inertia
        ixx="0.00031335734500024"
        ixy="-0.000541130398297199"
        ixz="-1.9132932863462E-08"
        iyy="0.00246254013905679"
        iyz="-3.66652071055823E-08"
        izz="0.00266671673580003" />
    </inertial>
    <visual>
      <origin
        xyz="0 0 0"
        rpy="0 0 0" />
      <geometry>
        <mesh
          filename="../meshes/link2.STL" />
      </geometry>
      <material
        name="">
        <color
          rgba="1 1 1 1" />
      </material>
    </visual>
    <collision>
      <origin
        xyz="0 0 0"
        rpy="0 0 0" />
      <geometry>
        <mesh
          filename="../meshes/link2.STL" />
      </geometry>
    </collision>
  </link>
  <joint
    name="joint2"
    type="revolute">
    <origin
      xyz="0.0225803798520988 -0.0220337569588361 0.0489000000003376"
      rpy="1.5707963267949 0 0.111028214146299" />
    <parent
      link="link1" />
    <child
      link="link2" />
    <axis
      xyz="0 0 -1" />
    <limit
      lower="-3.14"
      upper="3.14"
      effort="0"
      velocity="0.1" />
  </joint>
  <link
    name="link3">
    <inertial>
      <origin
        xyz="-0.0602442337639905 0.0838443251780994 -0.0240163415396901"
        rpy="0 0 0" />
      <mass
        value="0.489058615353727" />
      <inertia
        ixx="0.00207872833180645"
        ixy="0.000568534223762861"
        ixz="4.15748533644595E-08"
        iyy="0.00037578241588752"
        iyz="3.86287507981865E-09"
        izz="0.00233358466476932" />
    </inertial>
    <visual>
      <origin
        xyz="0 0 0"
        rpy="0 0 0" />
      <geometry>
        <mesh
          filename="../meshes/link3.STL" />
      </geometry>
      <material
        name="">
        <color
          rgba="1 1 1 1" />
      </material>
    </visual>
    <collision>
      <origin
        xyz="0 0 0"
        rpy="0 0 0" />
      <geometry>
        <mesh
          filename="../meshes/link3.STL" />
      </geometry>
    </collision>
  </link>
  <joint
    name="joint3"
    type="revolute">
    <origin
      xyz="0.31372987976612 0.0556095676499454 0"
      rpy="0 0 -1.39536543135007" />
    <parent
      link="link2" />
    <child
      link="link3" />
    <axis
      xyz="0 0 -1" />
    <limit
      lower="-3.14"
      upper="3.14"
      effort="0"
      velocity="0.1" />
  </joint>
  <link
    name="link4">
    <inertial>
      <origin
        xyz="0.00879296710355848 0.0229941238291514 -0.0234886181095875"
        rpy="0 0 0" />
      <mass
        value="0.233427532257575" />
      <inertia
        ixx="0.00018815166767764"
        ixy="-2.37983263258878E-05"
        ixz="-3.40106493586668E-09"
        iyy="0.00013643257043714"
        iyz="4.09756304996088E-08"
        izz="0.000147601939175478" />
    </inertial>
    <visual>
      <origin
        xyz="0 0 0"
        rpy="0 0 0" />
      <geometry>
        <mesh
          filename="../meshes/link4.STL" />
      </geometry>
      <material
        name="">
        <color
          rgba="1 1 1 1" />
      </material>
    </visual>
    <collision>
      <origin
        xyz="0 0 0"
        rpy="0 0 0" />
      <geometry>
        <mesh
          filename="../meshes/link4.STL" />
      </geometry>
    </collision>
  </link>
  <joint
    name="joint4"
    type="revolute">
    <origin
      xyz="-0.119739543983627 0.269212264652694 0"
      rpy="0 0 -1.39405537845928" />
    <parent
      link="link3" />
    <child
      link="link4" />
    <axis
      xyz="0 0 -1" />
    <limit
      lower="-3.14"
      upper="3.14"
      effort="0"
      velocity="0.1" />
  </joint>
  <link
    name="link5">
    <inertial>
      <origin
        xyz="4.5102810375397E-15 -2.64233079860787E-14 0.000886092892656065"
        rpy="0 0 0" />
      <mass
        value="0.000616109516267945" />
      <inertia
        ixx="1.53404132361036E-08"
        ixy="-2.05761177372566E-23"
        ixz="-2.48961977332855E-24"
        iyy="1.53404132361037E-08"
        iyz="-7.22490566276785E-24"
        izz="2.93869699527221E-08" />
    </inertial>
    <visual>
      <origin
        xyz="0 0 0"
        rpy="0 0 0" />
      <geometry>
        <mesh
          filename="../meshes/link5.STL" />
      </geometry>
      <material
        name="">
        <color
          rgba="1 1 1 1" />
      </material>
    </visual>
    <collision>
      <origin
        xyz="0 0 0"
        rpy="0 0 0" />
      <geometry>
        <mesh
          filename="../meshes/link5.STL" />
      </geometry>
    </collision>
  </link>
  <joint
    name="joint5"
    type="revolute">
    <origin
      xyz="0.0250377384169529 0.0971256101915153 -0.0244999999998483"
      rpy="1.22364489414134 -1.5707963267949 0" />
    <parent
      link="link4" />
    <child
      link="link5" />
    <axis
      xyz="0 0 -1" />
    <limit
      lower="-3.14"
      upper="3.14"
      effort="0"
      velocity="0.1" />
  </joint>
</robot>