<?xml version="1.0" encoding="utf-8"?>
<!-- This URDF was automatically created by SolidWorks to URDF Exporter! Originally created by Stephen Brawner (brawner@gmail.com) 
     Commit Version: 1.6.0-4-g7f85cfe  Build Version: 1.6.7995.38578
     For more information, please see http://wiki.ros.org/sw_urdf_exporter -->
<robot
  name="ice_cream_SINGLE.SLDASM">
  <link
    name="link0">
    <inertial>
      <origin
        xyz="0.125665458896186 0.131059805753843 0.0429362422311504"
        rpy="0 0 0" />
      <mass
        value="1.11408550189297" />
      <inertia
        ixx="0.00482403020893481"
        ixy="2.32804416690248E-07"
        ixz="2.19564408540003E-07"
        iyy="0.00514058299985557"
        iyz="-0.000227508420565635"
        izz="0.00836164871150541" />
    </inertial>
    <visual>
      <origin
        xyz="0 0 0"
        rpy="0 0 0" />
      <geometry>
        <mesh
          filename="package://ice_cream_SINGLE.SLDASM/meshes/link0.STL" />
      </geometry>
      <material
        name="">
        <color
          rgba="1 1 1 1" />
      </material>
    </visual>
    <collision>
      <origin
        xyz="0 0 0"
        rpy="0 0 0" />
      <geometry>
        <mesh
          filename="package://ice_cream_SINGLE.SLDASM/meshes/link0.STL" />
      </geometry>
    </collision>
  </link>
  <link
    name="link1">
    <inertial>
      <origin
        xyz="-0.000253577892220136 0.000263713909224324 0.00313574171142128"
        rpy="0 0 0" />
      <mass
        value="0.18743825475262" />
      <inertia
        ixx="9.33943364157118E-05"
        ixy="-2.96516646214622E-05"
        ixz="-6.10738893315528E-06"
        iyy="0.000105111872664094"
        iyz="7.38972010145834E-06"
        izz="0.000133969676635047" />
    </inertial>
    <visual>
      <origin
        xyz="0 0 0"
        rpy="0 0 0" />
      <geometry>
        <mesh
          filename="package://ice_cream_SINGLE.SLDASM/meshes/link1.STL" />
      </geometry>
      <material
        name="">
        <color
          rgba="1 1 1 1" />
      </material>
    </visual>
    <collision>
      <origin
        xyz="0 0 0"
        rpy="0 0 0" />
      <geometry>
        <mesh
          filename="package://ice_cream_SINGLE.SLDASM/meshes/link1.STL" />
      </geometry>
    </collision>
  </link>
  <joint
    name="joint1"
    type="continuous">
    <origin
      xyz="0.125 0.125 0.1055"
      rpy="0 0 0" />
    <parent
      link="link0" />
    <child
      link="link1" />
    <axis
      xyz="0 0 -1" />
    <limit
      lower="-3.14"
      upper="3.14"
      effort="0"
      velocity="0.1" />
  </joint>
  <link
    name="link2">
    <inertial>
      <origin
        xyz="-0.110599135461605 0.00217274526349662 -0.0241061884604368"
        rpy="0 0 0" />
      <mass
        value="0.516704158649432" />
      <inertia
        ixx="0.000194410587619758"
        ixy="-0.000142070099111904"
        ixz="1.21824154514498E-09"
        iyy="0.00258301573116518"
        iyz="-4.21948244755413E-08"
        izz="0.0026680710850822" />
    </inertial>
    <visual>
      <origin
        xyz="0 0 0"
        rpy="0 0 0" />
      <geometry>
        <mesh
          filename="package://ice_cream_SINGLE.SLDASM/meshes/link2.STL" />
      </geometry>
      <material
        name="">
        <color
          rgba="1 1 1 1" />
      </material>
    </visual>
    <collision>
      <origin
        xyz="0 0 0"
        rpy="0 0 0" />
      <geometry>
        <mesh
          filename="package://ice_cream_SINGLE.SLDASM/meshes/link2.STL" />
      </geometry>
    </collision>
  </link>
  <joint
    name="joint2"
    type="continuous">
    <origin
      xyz="-0.0061512 -0.030944 0.0589"
      rpy="1.5708 0 -0.88285" />
    <parent
      link="link1" />
    <child
      link="link2" />
    <axis
      xyz="0 0 -1" />
    <limit
      lower="-3.14"
      upper="3.14"
      effort="0"
      velocity="0.1" />
  </joint>
  <link
    name="link3">
    <inertial>
      <origin
        xyz="0.102335540798554 0.0287445221718131 -0.0241062511984758"
        rpy="0 0 0" />
      <mass
        value="0.512139422940588" />
      <inertia
        ixx="0.000232457007475035"
        ixy="0.000171860918560415"
        ixz="3.94203839976834E-08"
        iyy="0.00213151784243829"
        iyz="-1.30445130066582E-10"
        izz="0.00224372299848995" />
    </inertial>
    <visual>
      <origin
        xyz="0 0 0"
        rpy="0 0 0" />
      <geometry>
        <mesh
          filename="package://ice_cream_SINGLE.SLDASM/meshes/link3.STL" />
      </geometry>
      <material
        name="">
        <color
          rgba="1 1 1 1" />
      </material>
    </visual>
    <collision>
      <origin
        xyz="0 0 0"
        rpy="0 0 0" />
      <geometry>
        <mesh
          filename="package://ice_cream_SINGLE.SLDASM/meshes/link3.STL" />
      </geometry>
    </collision>
  </link>
  <joint
    name="joint3"
    type="continuous">
    <origin
      xyz="-0.31862 -0.00047432 0"
      rpy="0 0 1.5723" />
    <parent
      link="link2" />
    <child
      link="link3" />
    <axis
      xyz="0 0 -1" />
    <limit
      lower="-3.14"
      upper="3.14"
      effort="0"
      velocity="0.1" />
  </joint>
  <link
    name="link4">
    <inertial>
      <origin
        xyz="-0.0155488102975302 0.0184569058930177 -0.0236488164726929"
        rpy="0 0 0" />
      <mass
        value="0.23798346894583" />
      <inertia
        ixx="0.00017765252225049"
        ixy="3.5699643111406E-05"
        ixz="-1.52826924026763E-09"
        iyy="0.000165244214453878"
        iyz="4.13194100274005E-08"
        izz="0.000148676879374488" />
    </inertial>
    <visual>
      <origin
        xyz="0 0 0"
        rpy="0 0 0" />
      <geometry>
        <mesh
          filename="package://ice_cream_SINGLE.SLDASM/meshes/link4.STL" />
      </geometry>
      <material
        name="">
        <color
          rgba="1 1 1 1" />
      </material>
    </visual>
    <collision>
      <origin
        xyz="0 0 0"
        rpy="0 0 0" />
      <geometry>
        <mesh
          filename="package://ice_cream_SINGLE.SLDASM/meshes/link4.STL" />
      </geometry>
    </collision>
  </link>
  <joint
    name="joint4"
    type="continuous">
    <origin
      xyz="0.29995 0.015407 0"
      rpy="0 0 2.9342" />
    <parent
      link="link3" />
    <child
      link="link4" />
    <axis
      xyz="0 0 -1" />
    <limit
      lower="-3.14"
      upper="3.14"
      effort="0"
      velocity="0.1" />
  </joint>
  <link
    name="link5">
    <inertial>
      <origin
        xyz="0.0023963291210829 -0.0121991647932459 0.04347652224022"
        rpy="0 0 0" />
      <mass
        value="0.181825443810856" />
      <inertia
        ixx="9.9380376212715E-05"
        ixy="9.04126204473836E-06"
        ixz="-1.76269500935411E-06"
        iyy="0.000170069879518456"
        iyz="1.27058612459195E-05"
        izz="0.000216204312758356" />
    </inertial>
    <visual>
      <origin
        xyz="0 0 0"
        rpy="0 0 0" />
      <geometry>
        <mesh
          filename="package://ice_cream_SINGLE.SLDASM/meshes/link5.STL" />
      </geometry>
      <material
        name="">
        <color
          rgba="1 1 1 1" />
      </material>
    </visual>
    <collision>
      <origin
        xyz="0 0 0"
        rpy="0 0 0" />
      <geometry>
        <mesh
          filename="package://ice_cream_SINGLE.SLDASM/meshes/link5.STL" />
      </geometry>
    </collision>
  </link>
  <joint
    name="joint5"
    type="continuous">
    <origin
      xyz="-0.072453 0.06936 -0.0245"
      rpy="-1.8856 -1.5708 1.1336" />
    <parent
      link="link4" />
    <child
      link="link5" />
    <axis
      xyz="0 0 -1" />
    <limit
      lower="-3.14"
      upper="3.14"
      effort="0"
      velocity="0.1" />
  </joint>
  <link
    name="fingerlink_R">
    <inertial>
      <origin
        xyz="0.00135856429196929 0.00788197476730634 -0.00970666712579327"
        rpy="0 0 0" />
      <mass
        value="0.0404058825515486" />
      <inertia
        ixx="1.22950385775506E-05"
        ixy="1.26216827880967E-07"
        ixz="1.48055620763256E-08"
        iyy="1.05866156110572E-05"
        iyz="-1.31236092667189E-06"
        izz="1.47069491847476E-05" />
    </inertial>
    <visual>
      <origin
        xyz="0 0 0"
        rpy="0 0 0" />
      <geometry>
        <mesh
          filename="package://ice_cream_SINGLE.SLDASM/meshes/fingerlink_R.STL" />
      </geometry>
      <material
        name="">
        <color
          rgba="1 1 1 1" />
      </material>
    </visual>
    <collision>
      <origin
        xyz="0 0 0"
        rpy="0 0 0" />
      <geometry>
        <mesh
          filename="package://ice_cream_SINGLE.SLDASM/meshes/fingerlink_R.STL" />
      </geometry>
    </collision>
  </link>
  <joint
    name="FINGER_RIGHT"
    type="prismatic">
    <origin
      xyz="0.0425 -0.00228 0.0871"
      rpy="1.5708 0 -1.5708" />
    <parent
      link="link5" />
    <child
      link="fingerlink_R" />
    <axis
      xyz="0 0 -1" />
    <limit
      lower="0"
      upper="0"
      effort="0"
      velocity="0" />
  </joint>
  <link
    name="fingerlink_L">
    <inertial>
      <origin
        xyz="0.00786951430592731 -0.00135990452051521 -0.00970666706052659"
        rpy="0 0 0" />
      <mass
        value="0.0404058821166734" />
      <inertia
        ixx="1.05866152825476E-05"
        ixy="-1.26222801509918E-07"
        ixz="-1.3123602427821E-06"
        iyy="1.22950381719396E-05"
        iyz="-1.48054882142105E-08"
        izz="1.47069489570392E-05" />
    </inertial>
    <visual>
      <origin
        xyz="0 0 0"
        rpy="0 0 0" />
      <geometry>
        <mesh
          filename="package://ice_cream_SINGLE.SLDASM/meshes/fingerlink_L.STL" />
      </geometry>
      <material
        name="">
        <color
          rgba="1 1 1 1" />
      </material>
    </visual>
    <collision>
      <origin
        xyz="0 0 0"
        rpy="0 0 0" />
      <geometry>
        <mesh
          filename="package://ice_cream_SINGLE.SLDASM/meshes/fingerlink_L.STL" />
      </geometry>
    </collision>
  </link>
  <joint
    name="FINGER_LEFT"
    type="prismatic">
    <origin
      xyz="-0.032489 -0.00228 0.08725"
      rpy="0 -1.5708 0" />
    <parent
      link="link5" />
    <child
      link="fingerlink_L" />
    <axis
      xyz="0 0 -1" />
    <limit
      lower="0"
      upper="0"
      effort="0"
      velocity="0" />
  </joint>
</robot>